# 错误处理

Python 有两种错误很容易辨认：语法错误和异常。

## 语法错误

ython 的语法错误或者称之为解析错，是初学者经常碰到的,如下

```python
>>> while True print('Hello world')#函数 print() 被检查到有错误，是它前面缺少了一个冒号 :
  File "<stdin>", line 1, in ?
    while True print('Hello world')
                   ^
SyntaxError: invalid syntax
```

## 异常

即便 Python 程序的语法是正确的，在运行它的时候，也有可能发生错误。运行期检测到的错误被称为异常。

大多数的异常都不会被程序处理，都以错误信息的形式展现在这里:

```py
>>> 10 * (1/0)             # 0 不能作为除数，触发异常
Traceback (most recent call last):
  File "<stdin>", line 1, in ?
ZeroDivisionError: division by zero
>>> 4 + spam*3             # spam 未定义，触发异常
Traceback (most recent call last):
  File "<stdin>", line 1, in ?
NameError: name 'spam' is not defined
>>> '2' + 2               # int 不能与 str 相加，触发异常
Traceback (most recent call last):
  File "<stdin>", line 1, in <module>
TypeError: can only concatenate str (not "int") to str
```

## 异常处理

### try/except

异常捕捉可以使用 `try/except` 语句

```py
while True:
    try:
        x = int(input("请输入一个数字: "))
        break
    except ValueError:
        print("您输入的不是数字，请再次尝试输入！")
```

try 语句按照如下方式工作；

- 首先，执行 try 子句（在关键字 try 和关键字 except 之间的语句）。

- 如果没有异常发生，忽略 except 子句，try 子句执行后结束。

- 如果在执行 try 子句的过程中发生了异常，那么 try 子句余下的部分将被忽略。如果异常的类型和 except 之后的名称相符，那么对应的 except 子句将被执行。

- 如果一个异常没有与任何的 except 匹配，那么这个异常将会传递给上层的 try 中。
  一个 except 子句可以同时处理多个异常，这些异常将被放在一个括号里成为一个元组

```py
except (RuntimeError, TypeError, NameError):
    pass
# =======
except RuntimeError:
    pass
except TypeError:
    pass
```

### try/except...else

`try/except` 语句还有一个可选的 `else` 子句，如果使用这个子句，那么必须放在所有的 except 子句之后

```py
for arg in sys.argv[1:]:
    try:
        f = open(arg, 'r')
    except IOError:
        print('cannot open', arg)
    else:
        print(arg, 'has', len(f.readlines()), 'lines')
        f.close()
```

### try-finally

try-finally 语句无论是否发生异常都将执行最后的代码

```py
try:
    runoob()
except AssertionError as error:
    print(error)
else:
    try:
        with open('file.log') as file:
            read_data = file.read()
    except FileNotFoundError as fnf_error:
        print(fnf_error)
finally:
    print('这句话，无论异常是否发生都会执行。')
```

## 抛出异常

Python 使用 `raise` 语句抛出一个指定的异常

```py
raise [Exception [, args [, traceback]]]

x = 10
if x > 5:#大于5就触发异常
    raise Exception('x 不能大于 5。x 的值为: {}'.format(x))
```

## 用户自定义异常

你可以通过创建一个新的异常类来拥有自己的异常。异常类继承自 Exception 类，可以直接继承，或者间接继承

```py
>>> class MyError(Exception):
        def __init__(self, value):
            self.value = value
        def __str__(self):
            return repr(self.value)

>>> try:
        raise MyError(2*2)
    except MyError as e:
        print('My exception occurred, value:', e.value)

My exception occurred, value: 4
>>> raise MyError('oops!')
Traceback (most recent call last):
  File "<stdin>", line 1, in ?
__main__.MyError: 'oops!'
```

## 定义清理行为

try 语句还有另外一个可选的子句，它定义了无论在任何情况下都会执行的清理行为

```py
>>> try:
...     raise KeyboardInterrupt
... finally:
...     print('Goodbye, world!')
...
Goodbye, world!
Traceback (most recent call last):
  File "<stdin>", line 2, in <module>
KeyboardInterrupt
```

## 预定义的清理行为

一些对象定义了标准的清理行为，无论系统是否成功的使用了它，一旦不需要它了，那么这个标准的清理行为就会执行  
关键词 with 语句就可以保证诸如文件之类的对象在使用完之后一定会正确的执行他的清理方法:

```py
with open("myfile.txt") as f:
    for line in f:
        print(line, end="")
```
